Workbook

Sheet combined_reports
A1: source_file | B1: yaw | C1: velocity | D1: Downforce ALL | E1: Drag ALL | F1: -Cl | G1: Cd | H1: ClA | I1: CdA | J1: Aerodynamic Efficiency | K1: Percent downforce on front tire | L1: Percent downforce on rear tire | M1: Cl Mean | N1: Cl Variance | O1: Cl CoV | P1: Cd Mean | Q1: Cd Variance | R1: Cd CoV | S1: AeroBalance Mean | T1: AeroBalance Variance | U1: AeroBalance CoV | V1: Downforce Front Wing ALL | W1: Drag Front Wing ALL | X1: Downforce wing front 1 | Y1: Downforce wing front 2 | Z1: Downforce wing front 3 | AA1: Downforce wing front 4 | AB1: Downforce wing front 5 | AC1: Drag wing front 1 | AD1: Drag wing front 2 | AE1: Drag wing front 3 | AF1: Drag wing front 4 | AG1: Drag wing front 5 | AH1: Downforce wing front end plate 1 | AI1: Downforce wing front end plate 2 | AJ1: Downforce wing front end plate 3 | AK1: Drag wing front end plate 1 | AL1: Drag wing front end plate 2 | AM1: Drag wing front end plate 3 | AN1: Downforce Jacking Bar | AO1: Drag Jacking Bar | AP1: Downforce Rear Wing ALL | AQ1: Drag Rear Wing ALL | AR1: Downforce wing rear 1 | AS1: Downforce wing rear 2 | AT1: Downforce wing rear 3 | AU1: Downforce wing rear 4 | AV1: Downforce wing rear 5 | AW1: Drag wing rear 1 | AX1: Drag wing rear 2 | AY1: Drag wing rear 3 | AZ1: Drag wing rear 4 | BA1: Drag wing rear 5 | BB1: Downforce wing rear end plate | BC1: Drag wing rear end plate | BD1: Downforce Sidepods | BE1: Drag Sidepods | BF1: Downforce wing side 1 | BG1: Downforce wing side 2 | BH1: Downforce wing side 3 | BI1: Downforce wing side 4 | BJ1: Drag wing side 1 | BK1: Drag wing side 2 | BL1: Drag wing side 3 | BM1: Drag wing side 4 | BN1: Downforce Suspension Covers | BO1: Drag Suspension Covers | BP1: Downforce Moustaches | BQ1: Drag Moustaches | BR1: Downforce Diffuser | BS1: Drag Diffuser | BT1: Downforce Chassis | BU1: Drag Chassis | BV1: Downforce Center body | BW1: Drag Center body | BX1: Nosecone Cl | BY1: Nosecone Cd | BZ1: Nosecone FA | CA1: Downforce Suspension | CB1: Drag Suspension | CC1: Downforce Powertrain | CD1: Drag Powertrain | CE1: Downforce Mounts | CF1: Drag Mounts | CG1: Downforce Intake manifold | CH1: Drag Intake manifold | CI1: Drag wheel front | CJ1: Drag wheel rear | CK1: Front Tire Drag | CL1: Drag driver | CM1: Drag head rest | CN1: Downforce Radiator Shrouds | CO1: Drag Radiator Shrouds | CP1: Radiator Mass Flow | CQ1: Surface Average Fan Velocity | CR1: Fan volumetric flow rate | CS1: Mass Flow of fan | CT1: Force_x | CU1: Force_y | CV1: XF_Z | CW1: ZF_X | CX1: X_Coord | CY1: Z_Coord | CZ1: Planform area of the car | DA1: Frontal area of the car | DB1: Simulation Velocity | DC1: Density of Air | DD1: CFL Number | DE1: Solver Iteration Elapsed Time | DF1: Total Solver Elapsed Time | DG1: Average Solver Iteration Time
A2: Go4-26_BiggerDomain_FullCar_2__1__-2degyaw_10ms---_Reports.csv | B2: -2 | C2: 10 | D2: 239.44479 | E2: 93.204865 | F2: =D2/(0.5*DC2*DA2*(DB2^2)) -> 3.4109294 | G2: 1.3277183 | H2: 1.5264309 | I2: 0.59607276 | J2: 2.569016 | K2: 63.414031 | L2: 36.585969 | M2: 3.4023786 | N2: 2.0304961e-05 | O2: 0.0013243978 | P2: 1.3292505 | Q2: 8.1168276e-06 | R2: 0.0021433166 | S2: 63.405497 | T2: 0.0049327329 | U2: 0.0011076866 | V2: 87.145655 | W2: 18.979896 | X2: 67.783484 | Y2: 5.587262 | Z2: 4.3328975 | AA2: 2.0366791 | AB2: 2.2237666 | AC2: 2.6411456 | AD2: 2.5329143 | AE2: 2.0264272 | AF2: 2.0190441 | AG2: 3.6918705 | AH2: 4.0419748 | AI2: 0.43343022 | AJ2: 0.70616142 | AK2: 1.6181269 | AL2: 0.32834257 | AM2: 0.43015406 | AN2: 0 | AO2: 0 | AP2: 90.651078 | AQ2: 47.21956 | AR2: 68.026263 | AS2: 20.494855 | AT2: 1.4564591 | AU2: 0 | AV2: 0 | AW2: 11.817531 | AX2: 25.976536 | AY2: 8.0314105 | AZ2: 0 | BA2: 0 | BB2: -0.78295859 | BC2: 1.3940825 | BD2: 62.45995 | BE2: 8.7409298 | BF2: 0 | BG2: 0 | BH2: 0 | BI2: 0 | BJ2: 0 | BK2: 0 | BL2: 0 | BM2: 0 | BN2: 0 | BO2: 0 | BP2: 0 | BQ2: 0 | BR2: 0 | BS2: 0 | BT2: -0.035280403 | BU2: 0.65522803 | BV2: 6.0023164 | BW2: 10.995808 | BX2: 0 | BY2: 0 | BZ2: 0 | CA2: -0.14008455 | CB2: 4.6482735 | CC2: 0 | CD2: 0 | CE2: 0 | CF2: 0 | CG2: 0 | CH2: 0 | CI2: 0.9579222 | CJ2: 1.6816369 | CK2: 0.9579222 | CL2: 2.6763458 | CM2: 0 | CN2: -0.653421 | CO2: -0.069880956 | CP2: 0.10777914 | CQ2: 0 | CR2: 0 | CS2: 0 | CT2: 93.204865 | CU2: -239.44479 | CV2: -229.92308 | CW2: 44.363963 | CX2: 0.96023422 | CY2: 0.47598334 | CZ2: 3.451659 | DA2: 1.1137216 | DB2: 10.415735 | DC2: 1.162 | DD2: 100 | DE2: 472.563 | DF2: 107.93394 | DG2: 485.70271
A3: Go4-26_BiggerDomain_FullCar_2_0degyaw_10ms_Reports.csv | B3: 0 | C3: 10 | D3: 242.03866 | E3: 94.606276 | F3: =D3/(0.5*DC3*DA3*(DB3^2)) -> 3.4460563 | G3: 1.3469689 | H3: 1.5421506 | I3: 0.60439549 | J3: 2.5583785 | K3: 62.975533 | L3: 37.024467 | M3: 3.4346666 | N3: 1.066845e-06 | O3: 0.00030072261 | P3: 1.3465103 | Q3: 2.2462712e-07 | R3: 0.00035198279 | S3: 62.970784 | T3: 7.5700552e-05 | U3: 0.00013816894 | V3: 86.79534 | W3: 18.77177 | X3: 67.390584 | Y3: 5.6043969 | Z3: 4.3662512 | AA3: 2.0534716 | AB3: 2.2151148 | AC3: 2.3915606 | AD3: 2.5420414 | AE3: 2.0339737 | AF3: 2.0326509 | AG3: 3.6738848 | AH3: 4.0266306 | AI3: 0.4337077 | AJ3: 0.70518305 | AK3: 1.6448744 | AL3: 0.33955814 | AM3: 0.43934161 | AN3: 0 | AO3: 0 | AP3: 91.821332 | AQ3: 48.362741 | AR3: 68.786935 | AS3: 20.917934 | AT3: 1.4367862 | AU3: 0 | AV3: 0 | AW3: 12.222178 | AX3: 26.598656 | AY3: 7.9579997 | AZ3: 0 | BA3: 0 | BB3: -0.75710995 | BC3: 1.5839065 | BD3: 63.878175 | BE3: 8.8900017 | BF3: 0 | BG3: 0 | BH3: 0 | BI3: 0 | BJ3: 0 | BK3: 0 | BL3: 0 | BM3: 0 | BN3: 0 | BO3: 0 | BP3: 0 | BQ3: 0 | BR3: 0 | BS3: 0 | BT3: -0.017894555 | BU3: 0.66777714 | BV3: 6.422974 | BW3: 11.401142 | BX3: 0 | BY3: 0 | BZ3: 0 | CA3: -0.1458251 | CB3: 4.6855299 | CC3: 0 | CD3: 0 | CE3: 0 | CF3: 0 | CG3: 0 | CH3: 0 | CI3: 0.97002346 | CJ3: 1.4731112 | CK3: 0.97002346 | CL3: 2.7107777 | CM3: 0 | CN3: -0.8191062 | CO3: -0.051876299 | CP3: 0.10639776 | CQ3: 0 | CR3: 0 | CS3: 0 | CT3: 94.606276 | CU3: -242.03866 | CV3: -234.47744 | CW3: 45.307342 | CX3: 0.96876025 | CY3: 0.47890419 | CZ3: 3.451008 | DA3: 1.1143109 | DB3: 10.415735 | DC3: 1.162 | DD3: 100 | DE3: 23.604 | DF3: 3.3717633 | DG3: 24.084024
A4: Go4-26_BiggerDomain_FullCar_2_-4degyaw_10ms_Reports.csv | B4: -4 | C4: 10 | D4: 235.03387 | E4: 91.650569 | F4: =D4/(0.5*DC4*DA4*(DB4^2)) -> 3.346445 | G4: 1.3049336 | H4: 1.4975733 | I4: 0.58555498 | J4: 2.5644562 | K4: 63.785716 | L4: 36.214284 | M4: 3.3360393 | N4: 1.3098835e-06 | O4: 0.00034307193 | P4: 1.304598 | Q4: 1.4341268e-08 | R4: 9.1794583e-05 | S4: 63.777174 | T4: 5.9026182e-05 | U4: 0.00012046394 | V4: 86.348361 | W4: 18.833513 | X4: 67.163895 | Y4: 5.5481231 | Z4: 4.2704704 | AA4: 2.0498973 | AB4: 2.1670687 | AC4: 2.6412671 | AD4: 2.4938515 | AE4: 1.9914404 | AF4: 2.0225922 | AG4: 3.6328188 | AH4: 3.9837508 | AI4: 0.43602397 | AJ4: 0.72913189 | AK4: 1.624022 | AL4: 0.33706602 | AM4: 0.45763611 | AN4: 0 | AO4: 0 | AP4: 88.501424 | AQ4: 45.887687 | AR4: 66.692156 | AS4: 19.807232 | AT4: 1.4015439 | AU4: 0 | AV4: 0 | AW4: 11.532149 | AX4: 25.175785 | AY4: 7.8688046 | AZ4: 0 | BA4: 0 | BB4: -0.80105205 | BC4: 1.3109485 | BD4: 61.150122 | BE4: 8.3746346 | BF4: 0 | BG4: 0 | BH4: 0 | BI4: 0 | BJ4: 0 | BK4: 0 | BL4: 0 | BM4: 0 | BN4: 0 | BO4: 0 | BP4: 0 | BQ4: 0 | BR4: 0 | BS4: 0 | BT4: -0.00589955 | BU4: 0.62313452 | BV4: 6.0579768 | BW4: 10.997761 | BX4: 0 | BY4: 0 | BZ4: 0 | CA4: -0.19368879 | CB4: 4.5926493 | CC4: 0 | CD4: 0 | CE4: 0 | CF4: 0 | CG4: 0 | CH4: 0 | CI4: 1.0485571 | CJ4: 1.9861913 | CK4: 1.0485571 | CL4: 2.6047616 | CM4: 0 | CN4: -0.36458363 | CO4: -0.081105949 | CP4: 0.11093237 | CQ4: 0 | CR4: 0 | CS4: 0 | CT4: 91.650569 | CU4: -235.03387 | CV4: -223.98906 | CW4: 43.229143 | CX4: 0.95300761 | CY4: 0.47167349 | CZ4: 3.4516555 | DA4: 1.1142708 | DB4: 10.415735 | DC4: 1.162 | DD4: 100 | DE4: 25.32 | DF4: 4.1648583 | DG4: 25.156862
A5: Go4-26_BiggerDomain_FullCar_2_-4degyaw_15ms_Copy_Reports.csv | B5: -4 | C5: 15 | D5: 941.42909 | E5: 355.99431 | F5: =D5/(0.5*DC5*DA5*(DB5^2)) -> 5.974504 | G5: 2.2592136 | H5: 2.6736605 | I5: 1.0137633 | J5: 2.644506 | K5: 64.243045 | L5: 35.756955 | M5: 3.4037462 | N5: 3.1647045e-06 | O5: 0.00052264814 | P5: 1.2934946 | Q5: 6.2486087e-06 | R5: 0.0019325335 | S5: 64.159135 | T5: 0.002398091 | U5: 0.00076326321 | V5: 348.69973 | W5: 75.031258 | X5: 271.31649 | Y5: 22.353834 | Z5: 16.893306 | AA5: 8.3419868 | AB5: 8.7700526 | AC5: 9.8671483 | AD5: 10.075559 | AE5: 7.8911848 | AF5: 8.1878526 | AG5: 14.723756 | AH5: 16.243321 | AI5: 1.8025061 | AJ5: 2.9782367 | AK5: 6.39177 | AL5: 1.3704724 | AM5: 1.7997586 | AN5: 0 | AO5: 0 | AP5: 352.59323 | AQ5: 178.20227 | AR5: 267.4067 | AS5: 76.484253 | AT5: 5.7217975 | AU5: 0 | AV5: 0 | AW5: 43.848816 | AX5: 97.350566 | AY5: 31.932979 | AZ5: 0 | BA5: 0 | BB5: -2.7413193 | BC5: 5.0699077 | BD5: 247.20415 | BE5: 33.094199 | BF5: 0 | BG5: 0 | BH5: 0 | BI5: 0 | BJ5: 0 | BK5: 0 | BL5: 0 | BM5: 0 | BN5: 0 | BO5: 0 | BP5: 0 | BQ5: 0 | BR5: 0 | BS5: 0 | BT5: -0.065552557 | BU5: 2.12613 | BV5: 19.784565 | BW5: 43.203682 | BX5: 0 | BY5: 0 | BZ5: 0 | CA5: 0.012560475 | CB5: 17.425517 | CC5: 0 | CD5: 0 | CE5: 0 | CF5: 0 | CG5: 0 | CH5: 0 | CI5: 3.7113854 | CJ5: 6.9005011 | CK5: 3.7113854 | CL5: 9.4699071 | CM5: 0 | CN5: -2.4154166 | CO5: -0.094487622 | CP5: 0.22315145 | CQ5: 0 | CR5: 0 | CS5: 0 | CT5: 355.99431 | CU5: -941.42909 | CV5: -888.81814 | CW5: 168.35469 | CX5: 0.94411587 | CY5: 0.47291401 | CZ5: 3.4516555 | DA5: 1.1142708 | DB5: 15.601252 | DC5: 1.162 | DD5: 100 | DE5: 49.926 | DF5: 6.9451094 | DG5: 25.002394
A6: Go4-26_BiggerDomain_FullCar_2_8degyaw_10ms_Reports.csv | B6: 8 | C6: 10 | D6: 216.79269 | E6: 86.719762 | F6: =D6/(0.5*DC6*DA6*(DB6^2)) -> 3.0865021 | G6: 1.234639 | H6: 1.3812459 | I6: 0.55397219 | J6: 2.4999225 | K6: 65.500101 | L6: 34.499899 | M6: 3.0831048 | N6: 5.4602761e-06 | O6: 0.00075791239 | P6: 1.2350415 | Q6: 2.0203888e-07 | R6: 0.00036394513 | S6: 65.471326 | T6: 0.00018066382 | U6: 0.00020529788 | V6: 82.951255 | W6: 17.766994 | X6: 64.792691 | Y6: 5.3505025 | Z6: 3.9271463 | AA6: 2.0073305 | AB6: 1.9925238 | AC6: 2.359509 | AD6: 2.4184791 | AE6: 1.8167006 | AF6: 1.9902291 | AG6: 3.4311892 | AH6: 3.7996225 | AI6: 0.42836956 | AJ6: 0.65306964 | AK6: 1.5498339 | AL6: 0.33280933 | AM6: 0.43705461 | AN6: 0 | AO6: 0 | AP6: 79.230091 | AQ6: 41.295736 | AR6: 60.055338 | AS6: 17.228278 | AT6: 1.2820822 | AU6: 0 | AV6: 0 | AW6: 10.200151 | AX6: 22.212887 | AY6: 7.6700269 | AZ6: 0 | BA6: 0 | BB6: -0.61769006 | BC6: 1.2126716 | BD6: 56.735263 | BE6: 7.6632694 | BF6: 0 | BG6: 0 | BH6: 0 | BI6: 0 | BJ6: 0 | BK6: 0 | BL6: 0 | BM6: 0 | BN6: 0 | BO6: 0 | BP6: 0 | BQ6: 0 | BR6: 0 | BS6: 0 | BT6: -0.045851071 | BU6: 0.61698674 | BV6: 5.5171582 | BW6: 10.640609 | BX6: 0 | BY6: 0 | BZ6: 0 | CA6: -0.20530969 | CB6: 4.3521575 | CC6: 0 | CD6: 0 | CE6: 0 | CF6: 0 | CG6: 0 | CH6: 0 | CI6: 1.4210163 | CJ6: 3.4022162 | CK6: 1.4210163 | CL6: 2.6224752 | CM6: 0 | CN6: -0.035815997 | CO6: -0.17009172 | CP6: 0.11128442 | CQ6: 0 | CR6: 0 | CS6: 0 | CT6: 86.719762 | CU6: -216.79269 | CV6: -199.37896 | CW6: 39.492027 | CX6: 0.91967567 | CY6: 0.45539823 | CZ6: 3.4519273 | DA6: 1.1143511 | DB6: 10.415735 | DC6: 1.162 | DD6: 100 | DE6: 705.081 | DF6: 100.09589 | DG6: 720.69039
A7: Go4-26_BiggerDomain_FullCar_2_NEG6degyaw_10ms_Copy_Reports.csv | B7: -6 | C7: 10 | D7: 242.03201 | E7: 94.595933 | F7: =D7/(0.5*DC7*DA7*(DB7^2)) -> 3.4459616 | G7: 1.3468217 | H7: 1.5421082 | I7: 0.60432942 | J7: 2.5585879 | K7: 62.974173 | L7: 37.025827 | M7: 3.4346251 | N7: 9.2746896e-07 | O7: 0.00028039506 | P7: 1.3465306 | Q7: 2.5277364e-07 | R7: 0.00037337881 | S7: 62.969336 | T7: 0.00011474688 | U7: 0.0001701145 | V7: 86.790811 | W7: 18.770706 | X7: 67.387318 | Y7: 5.6042092 | Z7: 4.3658496 | AA7: 2.0534553 | AB7: 2.2149027 | AC7: 2.3912927 | AD7: 2.5419952 | AE7: 2.0337955 | AF7: 2.0326436 | AG7: 3.6736595 | AH7: 4.0262299 | AI7: 0.43371106 | AJ7: 0.7051359 | AK7: 1.6447542 | AL7: 0.33956638 | AM7: 0.43933976 | AN7: 0 | AO7: 0 | AP7: 91.824699 | AQ7: 48.358737 | AR7: 68.791488 | AS7: 20.916386 | AT7: 1.4368549 | AU7: 0 | AV7: 0 | AW7: 12.220649 | AX7: 26.596907 | AY7: 7.9577103 | AZ7: 0 | BA7: 0 | BB7: -0.75688496 | BC7: 1.5834709 | BD7: 63.873198 | BE7: 8.8894415 | BF7: 0 | BG7: 0 | BH7: 0 | BI7: 0 | BJ7: 0 | BK7: 0 | BL7: 0 | BM7: 0 | BN7: 0 | BO7: 0 | BP7: 0 | BQ7: 0 | BR7: 0 | BS7: 0 | BT7: -0.017923399 | BU7: 0.66783493 | BV7: 6.4189325 | BW7: 11.402113 | BX7: 0 | BY7: 0 | BZ7: 0 | CA7: -0.14566977 | CB7: 4.6865924 | CC7: 0 | CD7: 0 | CE7: 0 | CF7: 0 | CG7: 0 | CH7: 0 | CI7: 0.96347707 | CJ7: 1.4723908 | CK7: 0.96347707 | CL7: 2.7118191 | CM7: 0 | CN7: -0.81711972 | CO7: -0.05240356 | CP7: 0.10643042 | CQ7: 0 | CR7: 0 | CS7: 0 | CT7: 94.595933 | CU7: -242.03201 | CV7: -234.47739 | CW7: 45.30504 | CX7: 0.9687867 | CY7: 0.47893222 | CZ7: 3.451008 | DA7: 1.1143109 | DB7: 10.415735 | DC7: 1.162 | DD7: 100 | DE7: 47.777 | DF7: 3.5341664 | DG7: 25.445998
A8: Go4-26_BiggerDomain_FullCar_2_NEG6degyaw_15ms_Reports.csv | B8: -6 | C8: 15 | D8: 547.05808 | E8: 211.61707 | F8: =D8/(0.5*DC8*DA8*(DB8^2)) -> 3.4915995 | G8: 1.3506465 | H8: 1.5625317 | I8: 0.60604563 | J8: 2.5851321 | K8: 63.15459 | L8: 36.84541 | M8: 3.4826994 | N8: 2.1407812e-07 | O8: 0.00013285263 | P8: 1.350686 | Q8: 1.8701804e-07 | R8: 0.00032017496 | S8: 63.166537 | T8: 6.0484414e-05 | U8: 0.00012312172 | V8: 196.69877 | W8: 42.296521 | X8: 152.7595 | Y8: 12.68702 | Z8: 9.8131128 | AA8: 4.6849154 | AB8: 5.036724 | AC8: 5.1457621 | AD8: 5.7660581 | AE8: 4.5759135 | AF8: 4.6188626 | AG8: 8.3799304 | AH8: 9.1073939 | AI8: 0.99613238 | AJ8: 1.6139653 | AK8: 3.6751014 | AL8: 0.77318693 | AM8: 0.98177562 | AN8: 0 | AO8: 0 | AP8: 207.45313 | AQ8: 108.34345 | AR8: 155.55632 | AS8: 46.901452 | AT8: 3.2989054 | AU8: 0 | AV8: 0 | AW8: 27.111433 | AX8: 59.701818 | AY8: 18.004509 | AZ8: 0 | BA8: 0 | BB8: -1.6024497 | BC8: 3.5256863 | BD8: 144.66863 | BE8: 19.817039 | BF8: 0 | BG8: 0 | BH8: 0 | BI8: 0 | BJ8: 0 | BK8: 0 | BL8: 0 | BM8: 0 | BN8: 0 | BO8: 0 | BP8: 0 | BQ8: 0 | BR8: 0 | BS8: 0 | BT8: -0.040405494 | BU8: 1.3661222 | BV8: 13.427976 | BW8: 26.005365 | BX8: 0 | BY8: 0 | BZ8: 0 | CA8: -0.10026222 | CB8: 10.250487 | CC8: 0 | CD8: 0 | CE8: 0 | CF8: 0 | CG8: 0 | CH8: 0 | CI8: 1.9343841 | CJ8: 3.3250911 | CK8: 1.9343841 | CL8: 5.8384913 | CM8: 0 | CN8: -1.9891943 | CO8: -0.062756259 | CP8: 0.15691928 | CQ8: 0 | CR8: 0 | CS8: 0 | CT8: 211.61707 | CU8: -547.05808 | CV8: -528.06362 | CW8: 101.59408 | CX8: 0.96527889 | CY8: 0.48008453 | CZ8: 3.451008 | DA8: 1.1143109 | DB8: 15.556549 | DC8: 1.162 | DD8: 100 | DE8: 44.234 | DF8: 3.4805294 | DG8: 25.059812
A9: Go4-26_BiggerDomain_FullCar_2_NEG8degyaw_15ms_Reports.csv | B9: -8 | C9: 15 | D9: 489.79078 | E9: 192.76463 | F9: =D9/(0.5*DC9*DA9*(DB9^2)) -> 3.1259409 | G9: 1.2302617 | H9: 1.3988952 | I9: 0.5520016 | J9: 2.5408748 | K9: 65.959935 | L9: 34.040065 | M9: 3.1305646 | N9: 3.6591412e-05 | O9: 0.001932266 | P9: 1.2361451 | Q9: 1.0839797e-05 | R9: 0.002663429 | S9: 65.722239 | T9: 0.012896463 | U9: 0.0017279173 | V9: 189.17215 | W9: 40.115797 | X9: 147.73684 | Y9: 12.111425 | Z9: 8.9842108 | AA9: 4.5373566 | AB9: 4.5834938 | AC9: 5.1298098 | AD9: 5.4823031 | AE9: 4.1551802 | AF9: 4.4887223 | AG9: 7.8382453 | AH9: 8.7287853 | AI9: 0.97774387 | AJ9: 1.5122901 | AK9: 3.472398 | AL9: 0.74548761 | AM9: 0.9654056 | AN9: 0 | AO9: 0 | AP9: 177.09612 | AQ9: 92.319982 | AR9: 134.12035 | AS9: 38.358057 | AT9: 2.9983312 | AU9: 0 | AV9: 0 | AW9: 22.070048 | AX9: 49.938612 | AY9: 17.625513 | AZ9: 0 | BA9: 0 | BB9: -1.3789565 | BC9: 2.6858077 | BD9: 128.36211 | BE9: 17.70737 | BF9: 0 | BG9: 0 | BH9: 0 | BI9: 0 | BJ9: 0 | BK9: 0 | BL9: 0 | BM9: 0 | BN9: 0 | BO9: 0 | BP9: 0 | BQ9: 0 | BR9: 0 | BS9: 0 | BT9: -0.16253244 | BU9: 1.1679871 | BV9: 12.153773 | BW9: 24.116474 | BX9: 0 | BY9: 0 | BZ9: 0 | CA9: -0.26803343 | CB9: 9.5028 | CC9: 0 | CD9: 0 | CE9: 0 | CF9: 0 | CG9: 0 | CH9: 0 | CI9: 2.9032707 | CJ9: 6.7355774 | CK9: 2.9032707 | CL9: 5.3371911 | CM9: 0 | CN9: -0.11641647 | CO9: -0.49550286 | CP9: 0.17173051 | CQ9: 0 | CR9: 0 | CS9: 0 | CT9: 192.76463 | CU9: -489.79078 | CV9: -446.06941 | CW9: 88.305504 | CX9: 0.9107346 | CY9: 0.45810014 | CZ9: 3.4510638 | DA9: 1.1143643 | DB9: 15.556549 | DC9: 1.162 | DD9: 100 | DE9: 44.936 | DF9: 3.8150664 | DG9: 27.468478
A10: Go4-26_BiggerDomain_FullCar_2_zeroyaw_10ms.csv | B10: 0 | C10: 10 | D10: 242.03345 | E10: 94.638943 | F10: =D10/(0.5*DC10*DA10*(DB10^2)) -> 3.4459771 | G10: 1.3474321 | H10: 1.5421151 | I10: 0.60460247 | J10: 2.5574403 | K10: 62.984089 | L10: 37.015911 | M10: 3.4354891 | N10: 1.0696612e-06 | O10: 0.00030104718 | P10: 1.3468297 | Q10: 4.5074339e-07 | R10: 0.00049848489 | S10: 62.985162 | T10: 6.516394e-05 | U10: 0.00012816381 | V10: 86.8432 | W10: 18.805791 | X10: 67.424028 | Y10: 5.6064565 | Z10: 4.3687846 | AA10: 2.054855 | AB10: 2.2217121 | AC10: 2.3918405 | AD10: 2.5430669 | AE10: 2.0352445 | AF10: 2.0338468 | AG10: 3.6887186 | AH10: 4.0302053 | AI10: 0.43188095 | AJ10: 0.70527773 | AK10: 1.6450233 | AL10: 0.33988581 | AM10: 0.43944624 | AN10: 0 | AO10: 0 | AP10: 91.838642 | AQ10: 48.414592 | AR10: 68.777756 | AS10: 20.944165 | AT10: 1.4378492 | AU10: 0 | AV10: 0 | AW10: 12.238472 | AX10: 26.629104 | AY10: 7.962991 | AZ10: 0 | BA10: 0 | BB10: -0.75897742 | BC10: 1.5840243 | BD10: 63.744862 | BE10: 8.8900828 | BF10: 0 | BG10: 0 | BH10: 0 | BI10: 0 | BJ10: 0 | BK10: 0 | BL10: 0 | BM10: 0 | BN10: 0 | BO10: 0 | BP10: 0 | BQ10: 0 | BR10: 0 | BS10: 0 | BT10: -0.01646053 | BU10: 0.6674698 | BV10: 6.4358402 | BW10: 11.390655 | BX10: 0 | BY10: 0 | BZ10: 0 | CA10: -0.14563511 | CB10: 4.683699 | CC10: 0 | CD10: 0 | CE10: 0 | CF10: 0 | CG10: 0 | CH10: 0 | CI10: 0.96583831 | CJ10: 1.4582242 | CK10: 0.96583831 | CL10: 2.7097479 | CM10: 0 | CN10: -0.80634519 | CO10: -0.055629433 | CP10: 0.10622059 | CQ10: 0 | CR10: 0 | CS10: 0 | CT10: 94.638943 | CU10: -242.03345 | CV10: -234.43212 | CW10: 45.34777 | CX10: 0.9685939 | CY10: 0.47916606 | CZ10: 3.451007 | DA10: 1.1143125 | DB10: 10.415735 | DC10: 1.162 | DD10: 100 | DE10: 21.995 | DF10: 3.1664567 | DG10: 22.177518
A11: Go4-26_BiggerDomain_FullCar_2_zeroyaw_13ms.csv | B11: 0 | C11: 13 | D11: 380.90891 | E11: 147.91425 | F11: =D11/(0.5*DC11*DA11*(DB11^2)) -> 3.4768343 | G11: 1.3501216 | H11: 1.5559242 | I11: 0.60580923 | J11: 2.575201 | K11: 63.041249 | L11: 36.958751 | M11: 3.4602454 | N11: 1.9198889e-05 | O11: 0.0012662841 | P11: 1.3484483 | Q11: 5.4693424e-06 | R11: 0.001734336 | S11: 63.072675 | T11: 0.00033087336 | U11: 0.00028839628 | V11: 136.71467 | W11: 29.478872 | X11: 106.16039 | Y11: 8.8172385 | Z11: 6.8502643 | AA11: 3.2444829 | AB11: 3.5001485 | AC11: 3.6573087 | AD11: 4.0034385 | AE11: 3.192149 | AF11: 3.2041066 | AG11: 5.815419 | AH11: 6.3395793 | AI11: 0.68627854 | AJ11: 1.1162936 | AK11: 2.5699447 | AL11: 0.5355257 | AM11: 0.68556092 | AN11: 0 | AO11: 0 | AP11: 144.51804 | AQ11: 75.70439 | AR11: 108.34249 | AS11: 32.767052 | AT11: 2.2789808 | AU11: 0 | AV11: 0 | AW11: 19.057992 | AX11: 41.667717 | AY11: 12.510526 | AZ11: 0 | BA11: 0 | BB11: -1.149461 | BC11: 2.4681552 | BD11: 100.6098 | BE11: 13.876207 | BF11: 0 | BG11: 0 | BH11: 0 | BI11: 0 | BJ11: 0 | BK11: 0 | BL11: 0 | BM11: 0 | BN11: 0 | BO11: 0 | BP11: 0 | BQ11: 0 | BR11: 0 | BS11: 0 | BT11: -0.027101857 | BU11: 0.99742229 | BV11: 9.6786733 | BW11: 18.0501 | BX11: 0 | BY11: 0 | BZ11: 0 | CA11: -0.13633768 | CB11: 7.244232 | CC11: 0 | CD11: 0 | CE11: 0 | CF11: 0 | CG11: 0 | CH11: 0 | CI11: 1.3758584 | CJ11: 2.2955378 | CK11: 1.3758584 | CL11: 4.1504009 | CM11: 0 | CN11: -1.3471216 | CO11: -0.063300039 | CP11: 0.13226333 | CQ11: 0 | CR11: 0 | CS11: 0 | CT11: 147.91425 | CU11: -380.90891 | CV11: -368.52272 | CW11: 70.933877 | CX11: 0.96748254 | CY11: 0.47956082 | CZ11: 3.451007 | DA11: 1.1143125 | DB11: 13.008494 | DC11: 1.162 | DD11: 100 | DE11: 37.37 | DF11: 6.2434122 | DG11: 22.476284
A12: Go4-26_BiggerDomain_FullCar_zeroyaw_18_Reports.csv | B12: 0 | C12: 18 | D12: 742.28975 | E12: 286.09659 | F12: =D12/(0.5*DC12*DA12*(DB12^2)) -> 3.4979393 | G12: 1.3481911 | H12: 1.5653688 | I12: 0.60494304 | J12: 2.5945425 | K12: 63.274978 | L12: 36.725022 | M12: 3.4868574 | N12: 2.867015e-06 | O12: 0.00048560236 | P12: 1.3487928 | Q12: 3.5278122e-07 | R12: 0.00044035963 | S12: 63.254734 | T12: 0.0011460642 | U12: 0.00053519424 | V12: 267.48103 | W12: 57.460658 | X12: 207.73206 | Y12: 17.268606 | Z12: 13.289579 | AA12: 6.4006295 | AB12: 6.8535406 | AC12: 6.8849207 | AD12: 7.8542957 | AE12: 6.2020012 | AF12: 6.3017639 | AG12: 11.425039 | AH12: 12.368096 | AI12: 1.3661898 | AJ12: 2.2023327 | AK12: 4.977714 | AL12: 1.0581581 | AM12: 1.3317261 | AN12: 0 | AO12: 0 | AP12: 281.90147 | AQ12: 147.3589 | AR12: 211.24751 | AS12: 63.76306 | AT12: 4.5212462 | AU12: 0 | AV12: 0 | AW12: 36.787463 | AX12: 81.190977 | AY12: 24.581942 | AZ12: 0 | BA12: 0 | BB12: -2.1515947 | BC12: 4.7985214 | BD12: 195.91017 | BE12: 26.680039 | BF12: 0 | BG12: 0 | BH12: 0 | BI12: 0 | BJ12: 0 | BK12: 0 | BL12: 0 | BM12: 0 | BN12: 0 | BO12: 0 | BP12: 0 | BQ12: 0 | BR12: 0 | BS12: 0 | BT12: -0.05005011 | BU12: 1.7653762 | BV12: 17.36059 | BW12: 34.708922 | BX12: 0 | BY12: 0 | BZ12: 0 | CA12: -0.050774594 | CB12: 13.666861 | CC12: 0 | CD12: 0 | CE12: 0 | CF12: 0 | CG12: 0 | CH12: 0 | CI12: 2.5544765 | CJ12: 4.4337624 | CK12: 2.5544765 | CL12: 7.7597462 | CM12: 0 | CN12: -2.6863321 | CO12: -0.055747176 | CP12: 0.18224588 | CQ12: 0 | CR12: 0 | CS12: 0 | CT12: 286.09659 | CU12: -742.28975 | CV12: -714.77916 | CW12: 138.03202 | CX12: 0.9629382 | CY12: 0.4824665 | CZ12: 3.451007 | DA12: 1.1143125 | DB12: 18.104604 | DC12: 1.162 | DD12: 100 | DE12: 72.54 | DF12: 7.1264039 | DG12: 63.977691
A13: Go4-26_BiggerDomain_FullCar_zeroyaw_20_7ms_Reports.csv | B13: 0 | C13: 20 | D13: 967.953 | E13: 372.38106 | F13: =D13/(0.5*DC13*DA13*(DB13^2)) -> 3.4901262 | G13: 1.342686 | H13: 1.5618724 | I13: 0.60247284 | J13: 2.5993615 | K13: 63.334096 | L13: 36.665904 | M13: 3.4795099 | N13: 1.4796122e-05 | O13: 0.0011054927 | P13: 1.3437384 | Q13: 1.2495182e-06 | R13: 0.00083187214 | S13: 63.294769 | T13: 0.0005724516 | U13: 0.0003780085 | V13: 349.921 | W13: 75.0037 | X13: 271.84073 | Y13: 22.591617 | Z13: 17.26933 | AA13: 8.3895096 | AB13: 8.9546806 | AC13: 8.8626922 | AD13: 10.283823 | AE13: 8.060421 | AF13: 8.2547155 | AG13: 14.961356 | AH13: 16.189589 | AI13: 1.7998579 | AJ13: 2.885686 | AK13: 6.4925921 | AL13: 1.3908208 | AM13: 1.7359231 | AN13: 0 | AO13: 0 | AP13: 369.18802 | AQ13: 190.61836 | AR13: 277.4761 | AS13: 82.706534 | AT13: 5.9136083 | AU13: 0 | AV13: 0 | AW13: 46.839076 | AX13: 105.3071 | AY13: 32.320658 | AZ13: 0 | BA13: 0 | BB13: -2.8218308 | BC13: 6.1515241 | BD13: 256.28078 | BE13: 34.528187 | BF13: 0 | BG13: 0 | BH13: 0 | BI13: 0 | BJ13: 0 | BK13: 0 | BL13: 0 | BM13: 0 | BN13: 0 | BO13: 0 | BP13: 0 | BQ13: 0 | BR13: 0 | BS13: 0 | BT13: -0.084116378 | BU13: 2.2968496 | BV13: 19.148853 | BW13: 45.416481 | BX13: 0 | BY13: 0 | BZ13: 0 | CA13: 0.020817194 | CB13: 18.456309 | CC13: 0 | CD13: 0 | CE13: 0 | CF13: 0 | CG13: 0 | CH13: 0 | CI13: 3.1949885 | CJ13: 6.0141214 | CK13: 3.1949885 | CL13: 10.350069 | CM13: 0 | CN13: -3.0423184 | CO13: 0.027113645 | CP13: 0.20544148 | CQ13: 0 | CR13: 0 | CS13: 0 | CT13: 372.38106 | CU13: -967.953 | CV13: -930.96633 | CW13: 179.49514 | CX13: 0.96178877 | CY13: 0.48202006 | CZ13: 3.451007 | DA13: 1.1143125 | DB13: 20.697363 | DC13: 1.162 | DD13: 100 | DE13: 40.878 | DF13: 9.6219475 | DG13: 56.785264
... A27: Go4-26_BiggerDomain_FullCar_2_NEG8degyaw_15ms_Reports.csv | B27: -8 | C27: 15 | D27: 489.79078 | E27: 192.76463 | F27: =D27/(0.5*DC27*DA27*(DB27^2)) -> 3.1259409 | G27: 1.2302617 | H27: 1.3988952 | I27: 0.5520016 | J27: 2.5408748 | K27: 65.959935 | L27: 34.040065 | M27: 3.1305646 | N27: 3.6591412e-05 | O27: 0.001932266 | P27: 1.2361451 | Q27: 1.0839797e-05 | R27: 0.002663429 | S27: 65.722239 | T27: 0.012896463 | U27: 0.0017279173 | V27: 189.17215 | W27: 40.115797 | X27: 147.73684 | Y27: 12.111425 | Z27: 8.9842108 | AA27: 4.5373566 | AB27: 4.5834938 | AC27: 5.1298098 | AD27: 5.4823031 | AE27: 4.1551802 | AF27: 4.4887223 | AG27: 7.8382453 | AH27: 8.7287853 | AI27: 0.97774387 | AJ27: 1.5122901 | AK27: 3.472398 | AL27: 0.74548761 | AM27: 0.9654056 | AN27: 0 | AO27: 0 | AP27: 177.09612 | AQ27: 92.319982 | AR27: 134.12035 | AS27: 38.358057 | AT27: 2.9983312 | AU27: 0 | AV27: 0 | AW27: 22.070048 | AX27: 49.938612 | AY27: 17.625513 | AZ27: 0 | BA27: 0 | BB27: -1.3789565 | BC27: 2.6858077 | BD27: 128.36211 | BE27: 17.70737 | BF27: 0 | BG27: 0 | BH27: 0 | BI27: 0 | BJ27: 0 | BK27: 0 | BL27: 0 | BM27: 0 | BN27: 0 | BO27: 0 | BP27: 0 | BQ27: 0 | BR27: 0 | BS27: 0 | BT27: -0.16253244 | BU27: 1.1679871 | BV27: 12.153773 | BW27: 24.116474 | BX27: 0 | BY27: 0 | BZ27: 0 | CA27: -0.26803343 | CB27: 9.5028 | CC27: 0 | CD27: 0 | CE27: 0 | CF27: 0 | CG27: 0 | CH27: 0 | CI27: 2.9032707 | CJ27: 6.7355774 | CK27: 2.9032707 | CL27: 5.3371911 | CM27: 0 | CN27: -0.11641647 | CO27: -0.49550286 | CP27: 0.17173051 | CQ27: 0 | CR27: 0 | CS27: 0 | CT27: 192.76463 | CU27: -489.79078 | CV27: -446.06941 | CW27: 88.305504 | CX27: 0.9107346 | CY27: 0.45810014 | CZ27: 3.4510638 | DA27: 1.1143643 | DB27: 15.556549 | DC27: 1.162 | DD27: 100 | DE27: 44.936 | DF27: 3.8150664 | DG27: 27.468478

Sheet Sheet1
A1: 26 CFD DATA
A2: source_file | B2: yaw | C2: velocity | D2: Downforce ALL | E2: Drag ALL | F2: -Cl | G2: Cd | H2: ClA | I2: CdA | J2: Aerodynamic Efficiency | K2: Percent downforce on front tire | L2: Percent downforce on rear tire | M2: Cl Mean | N2: Cl Variance | O2: Cl CoV | P2: Cd Mean | Q2: Cd Variance | R2: Cd CoV | S2: AeroBalance Mean | T2: AeroBalance Variance | U2: AeroBalance CoV | V2: Downforce Front Wing ALL | W2: Drag Front Wing ALL | X2: Downforce wing front 1 | Y2: Downforce wing front 2 | Z2: Downforce wing front 3 | AA2: Downforce wing front 4 | AB2: Downforce wing front 5 | AC2: Drag wing front 1 | AD2: Drag wing front 2 | AE2: Drag wing front 3 | AF2: Drag wing front 4 | AG2: Drag wing front 5 | AH2: Downforce wing front end plate 1 | AI2: Downforce wing front end plate 2 | AJ2: Downforce wing front end plate 3 | AK2: Drag wing front end plate 1 | AL2: Drag wing front end plate 2 | AM2: Drag wing front end plate 3 | AN2: Downforce Jacking Bar | AO2: Drag Jacking Bar | AP2: Downforce Rear Wing ALL | AQ2: Drag Rear Wing ALL | AR2: Downforce wing rear 1 | AS2: Downforce wing rear 2 | AT2: Downforce wing rear 3 | AU2: Downforce wing rear 4 | AV2: Downforce wing rear 5 | AW2: Drag wing rear 1 | AX2: Drag wing rear 2 | AY2: Drag wing rear 3 | AZ2: Drag wing rear 4 | BA2: Drag wing rear 5 | BB2: Downforce wing rear end plate | BC2: Drag wing rear end plate | BD2: Downforce Sidepods | BE2: Drag Sidepods | BF2: Downforce wing side 1 | BG2: Downforce wing side 2 | BH2: Downforce wing side 3 | BI2: Downforce wing side 4 | BJ2: Drag wing side 1 | BK2: Drag wing side 2 | BL2: Drag wing side 3 | BM2: Drag wing side 4 | BN2: Downforce Suspension Covers | BO2: Drag Suspension Covers | BP2: Downforce Moustaches | BQ2: Drag Moustaches | BR2: Downforce Diffuser | BS2: Drag Diffuser | BT2: Downforce Chassis | BU2: Drag Chassis | BV2: Downforce Center body | BW2: Drag Center body | BX2: Nosecone Cl | BY2: Nosecone Cd | BZ2: Nosecone FA | CA2: Downforce Suspension | CB2: Drag Suspension | CC2: Downforce Powertrain | CD2: Drag Powertrain | CE2: Downforce Mounts | CF2: Drag Mounts | CG2: Downforce Intake manifold | CH2: Drag Intake manifold | CI2: Drag wheel front | CJ2: Drag wheel rear | CK2: Front Tire Drag | CL2: Drag driver | CM2: Drag head rest | CN2: Downforce Radiator Shrouds | CO2: Drag Radiator Shrouds | CP2: Radiator Mass Flow | CQ2: Surface Average Fan Velocity | CR2: Fan volumetric flow rate | CS2: Mass Flow of fan | CT2: Force_x | CU2: Force_y | CV2: XF_Z | CW2: ZF_X | CX2: X_Coord | CY2: Z_Coord | CZ2: Planform area of the car | DA2: Frontal area of the car | DB2: Simulation Velocity | DC2: Density of Air | DD2: CFL Number | DE2: Solver Iteration Elapsed Time | DF2: Total Solver Elapsed Time | DG2: Average Solver Iteration Time
A3: Go4-26_BiggerDomain_FullCar_2_0degyaw_10ms_Reports.csv | B3: 0 | C3: 10 | D3: 242.03866 | E3: 94.606276 | F3: =D3/(0.5*DC3*DA3*(DB3^2)) -> 3.4460563 | G3: 1.3469689 | H3: 1.5421506 | I3: 0.60439549 | J3: 2.5583785 | K3: 62.975533 | L3: 37.024467 | M3: 3.4346666 | N3: 1.066845e-06 | O3: 0.00030072261 | P3: 1.3465103 | Q3: 2.2462712e-07 | R3: 0.00035198279 | S3: 62.970784 | T3: 7.5700552e-05 | U3: 0.00013816894 | V3: 86.79534 | W3: 18.77177 | X3: 67.390584 | Y3: 5.6043969 | Z3: 4.3662512 | AA3: 2.0534716 | AB3: 2.2151148 | AC3: 2.3915606 | AD3: 2.5420414 | AE3: 2.0339737 | AF3: 2.0326509 | AG3: 3.6738848 | AH3: 4.0266306 | AI3: 0.4337077 | AJ3: 0.70518305 | AK3: 1.6448744 | AL3: 0.33955814 | AM3: 0.43934161 | AN3: 0 | AO3: 0 | AP3: 91.821332 | AQ3: 48.362741 | AR3: 68.786935 | AS3: 20.917934 | AT3: 1.4367862 | AU3: 0 | AV3: 0 | AW3: 12.222178 | AX3: 26.598656 | AY3: 7.9579997 | AZ3: 0 | BA3: 0 | BB3: -0.75710995 | BC3: 1.5839065 | BD3: 63.878175 | BE3: 8.8900017 | BF3: 0 | BG3: 0 | BH3: 0 | BI3: 0 | BJ3: 0 | BK3: 0 | BL3: 0 | BM3: 0 | BN3: 0 | BO3: 0 | BP3: 0 | BQ3: 0 | BR3: 0 | BS3: 0 | BT3: -0.017894555 | BU3: 0.66777714 | BV3: 6.422974 | BW3: 11.401142 | BX3: 0 | BY3: 0 | BZ3: 0 | CA3: -0.1458251 | CB3: 4.6855299 | CC3: 0 | CD3: 0 | CE3: 0 | CF3: 0 | CG3: 0 | CH3: 0 | CI3: 0.97002346 | CJ3: 1.4731112 | CK3: 0.97002346 | CL3: 2.7107777 | CM3: 0 | CN3: -0.8191062 | CO3: -0.051876299 | CP3: 0.10639776 | CQ3: 0 | CR3: 0 | CS3: 0 | CT3: 94.606276 | CU3: -242.03866 | CV3: -234.47744 | CW3: 45.307342 | CX3: 0.96876025 | CY3: 0.47890419 | CZ3: 3.451008 | DA3: 1.1143109 | DB3: 10.415735 | DC3: 1.162 | DD3: 100 | DE3: 23.604 | DF3: 3.3717633 | DG3: 24.084024
A4: Go4-26_BiggerDomain_FullCar_2_zeroyaw_10ms.csv | B4: 0 | C4: 10 | D4: 242.03345 | E4: 94.638943 | F4: =D4/(0.5*DC4*DA4*(DB4^2)) -> 3.4459771 | G4: 1.3474321 | H4: 1.5421151 | I4: 0.60460247 | J4: 2.5574403 | K4: 62.984089 | L4: 37.015911 | M4: 3.4354891 | N4: 1.0696612e-06 | O4: 0.00030104718 | P4: 1.3468297 | Q4: 4.5074339e-07 | R4: 0.00049848489 | S4: 62.985162 | T4: 6.516394e-05 | U4: 0.00012816381 | V4: 86.8432 | W4: 18.805791 | X4: 67.424028 | Y4: 5.6064565 | Z4: 4.3687846 | AA4: 2.054855 | AB4: 2.2217121 | AC4: 2.3918405 | AD4: 2.5430669 | AE4: 2.0352445 | AF4: 2.0338468 | AG4: 3.6887186 | AH4: 4.0302053 | AI4: 0.43188095 | AJ4: 0.70527773 | AK4: 1.6450233 | AL4: 0.33988581 | AM4: 0.43944624 | AN4: 0 | AO4: 0 | AP4: 91.838642 | AQ4: 48.414592 | AR4: 68.777756 | AS4: 20.944165 | AT4: 1.4378492 | AU4: 0 | AV4: 0 | AW4: 12.238472 | AX4: 26.629104 | AY4: 7.962991 | AZ4: 0 | BA4: 0 | BB4: -0.75897742 | BC4: 1.5840243 | BD4: 63.744862 | BE4: 8.8900828 | BF4: 0 | BG4: 0 | BH4: 0 | BI4: 0 | BJ4: 0 | BK4: 0 | BL4: 0 | BM4: 0 | BN4: 0 | BO4: 0 | BP4: 0 | BQ4: 0 | BR4: 0 | BS4: 0 | BT4: -0.01646053 | BU4: 0.6674698 | BV4: 6.4358402 | BW4: 11.390655 | BX4: 0 | BY4: 0 | BZ4: 0 | CA4: -0.14563511 | CB4: 4.683699 | CC4: 0 | CD4: 0 | CE4: 0 | CF4: 0 | CG4: 0 | CH4: 0 | CI4: 0.96583831 | CJ4: 1.4582242 | CK4: 0.96583831 | CL4: 2.7097479 | CM4: 0 | CN4: -0.80634519 | CO4: -0.055629433 | CP4: 0.10622059 | CQ4: 0 | CR4: 0 | CS4: 0 | CT4: 94.638943 | CU4: -242.03345 | CV4: -234.43212 | CW4: 45.34777 | CX4: 0.9685939 | CY4: 0.47916606 | CZ4: 3.451007 | DA4: 1.1143125 | DB4: 10.415735 | DC4: 1.162 | DD4: 100 | DE4: 21.995 | DF4: 3.1664567 | DG4: 22.177518
A5: Go4-26_BiggerDomain_FullCar_2_zeroyaw_13ms.csv | B5: 0 | C5: 13 | D5: 380.90891 | E5: 147.91425 | F5: =D5/(0.5*DC5*DA5*(DB5^2)) -> 3.4768343 | G5: 1.3501216 | H5: 1.5559242 | I5: 0.60580923 | J5: 2.575201 | K5: 63.041249 | L5: 36.958751 | M5: 3.4602454 | N5: 1.9198889e-05 | O5: 0.0012662841 | P5: 1.3484483 | Q5: 5.4693424e-06 | R5: 0.001734336 | S5: 63.072675 | T5: 0.00033087336 | U5: 0.00028839628 | V5: 136.71467 | W5: 29.478872 | X5: 106.16039 | Y5: 8.8172385 | Z5: 6.8502643 | AA5: 3.2444829 | AB5: 3.5001485 | AC5: 3.6573087 | AD5: 4.0034385 | AE5: 3.192149 | AF5: 3.2041066 | AG5: 5.815419 | AH5: 6.3395793 | AI5: 0.68627854 | AJ5: 1.1162936 | AK5: 2.5699447 | AL5: 0.5355257 | AM5: 0.68556092 | AN5: 0 | AO5: 0 | AP5: 144.51804 | AQ5: 75.70439 | AR5: 108.34249 | AS5: 32.767052 | AT5: 2.2789808 | AU5: 0 | AV5: 0 | AW5: 19.057992 | AX5: 41.667717 | AY5: 12.510526 | AZ5: 0 | BA5: 0 | BB5: -1.149461 | BC5: 2.4681552 | BD5: 100.6098 | BE5: 13.876207 | BF5: 0 | BG5: 0 | BH5: 0 | BI5: 0 | BJ5: 0 | BK5: 0 | BL5: 0 | BM5: 0 | BN5: 0 | BO5: 0 | BP5: 0 | BQ5: 0 | BR5: 0 | BS5: 0 | BT5: -0.027101857 | BU5: 0.99742229 | BV5: 9.6786733 | BW5: 18.0501 | BX5: 0 | BY5: 0 | BZ5: 0 | CA5: -0.13633768 | CB5: 7.244232 | CC5: 0 | CD5: 0 | CE5: 0 | CF5: 0 | CG5: 0 | CH5: 0 | CI5: 1.3758584 | CJ5: 2.2955378 | CK5: 1.3758584 | CL5: 4.1504009 | CM5: 0 | CN5: -1.3471216 | CO5: -0.063300039 | CP5: 0.13226333 | CQ5: 0 | CR5: 0 | CS5: 0 | CT5: 147.91425 | CU5: -380.90891 | CV5: -368.52272 | CW5: 70.933877 | CX5: 0.96748254 | CY5: 0.47956082 | CZ5: 3.451007 | DA5: 1.1143125 | DB5: 13.008494 | DC5: 1.162 | DD5: 100 | DE5: 37.37 | DF5: 6.2434122 | DG5: 22.476284
A6: Go4-26_BiggerDomain_FullCar_zeroyaw_18_Reports.csv | B6: 0 | C6: 18 | D6: 742.28975 | E6: 286.09659 | F6: =D6/(0.5*DC6*DA6*(DB6^2)) -> 3.4979393 | G6: 1.3481911 | H6: 1.5653688 | I6: 0.60494304 | J6: 2.5945425 | K6: 63.274978 | L6: 36.725022 | M6: 3.4868574 | N6: 2.867015e-06 | O6: 0.00048560236 | P6: 1.3487928 | Q6: 3.5278122e-07 | R6: 0.00044035963 | S6: 63.254734 | T6: 0.0011460642 | U6: 0.00053519424 | V6: 267.48103 | W6: 57.460658 | X6: 207.73206 | Y6: 17.268606 | Z6: 13.289579 | AA6: 6.4006295 | AB6: 6.8535406 | AC6: 6.8849207 | AD6: 7.8542957 | AE6: 6.2020012 | AF6: 6.3017639 | AG6: 11.425039 | AH6: 12.368096 | AI6: 1.3661898 | AJ6: 2.2023327 | AK6: 4.977714 | AL6: 1.0581581 | AM6: 1.3317261 | AN6: 0 | AO6: 0 | AP6: 281.90147 | AQ6: 147.3589 | AR6: 211.24751 | AS6: 63.76306 | AT6: 4.5212462 | AU6: 0 | AV6: 0 | AW6: 36.787463 | AX6: 81.190977 | AY6: 24.581942 | AZ6: 0 | BA6: 0 | BB6: -2.1515947 | BC6: 4.7985214 | BD6: 195.91017 | BE6: 26.680039 | BF6: 0 | BG6: 0 | BH6: 0 | BI6: 0 | BJ6: 0 | BK6: 0 | BL6: 0 | BM6: 0 | BN6: 0 | BO6: 0 | BP6: 0 | BQ6: 0 | BR6: 0 | BS6: 0 | BT6: -0.05005011 | BU6: 1.7653762 | BV6: 17.36059 | BW6: 34.708922 | BX6: 0 | BY6: 0 | BZ6: 0 | CA6: -0.050774594 | CB6: 13.666861 | CC6: 0 | CD6: 0 | CE6: 0 | CF6: 0 | CG6: 0 | CH6: 0 | CI6: 2.5544765 | CJ6: 4.4337624 | CK6: 2.5544765 | CL6: 7.7597462 | CM6: 0 | CN6: -2.6863321 | CO6: -0.055747176 | CP6: 0.18224588 | CQ6: 0 | CR6: 0 | CS6: 0 | CT6: 286.09659 | CU6: -742.28975 | CV6: -714.77916 | CW6: 138.03202 | CX6: 0.9629382 | CY6: 0.4824665 | CZ6: 3.451007 | DA6: 1.1143125 | DB6: 18.104604 | DC6: 1.162 | DD6: 100 | DE6: 72.54 | DF6: 7.1264039 | DG6: 63.977691
A7: Go4-26_BiggerDomain_FullCar_zeroyaw_20_7ms_Reports.csv | B7: 0 | C7: 20 | D7: 967.953 | E7: 372.38106 | F7: =D7/(0.5*DC7*DA7*(DB7^2)) -> 3.4901262 | G7: 1.342686 | H7: 1.5618724 | I7: 0.60247284 | J7: 2.5993615 | K7: 63.334096 | L7: 36.665904 | M7: 3.4795099 | N7: 1.4796122e-05 | O7: 0.0011054927 | P7: 1.3437384 | Q7: 1.2495182e-06 | R7: 0.00083187214 | S7: 63.294769 | T7: 0.0005724516 | U7: 0.0003780085 | V7: 349.921 | W7: 75.0037 | X7: 271.84073 | Y7: 22.591617 | Z7: 17.26933 | AA7: 8.3895096 | AB7: 8.9546806 | AC7: 8.8626922 | AD7: 10.283823 | AE7: 8.060421 | AF7: 8.2547155 | AG7: 14.961356 | AH7: 16.189589 | AI7: 1.7998579 | AJ7: 2.885686 | AK7: 6.4925921 | AL7: 1.3908208 | AM7: 1.7359231 | AN7: 0 | AO7: 0 | AP7: 369.18802 | AQ7: 190.61836 | AR7: 277.4761 | AS7: 82.706534 | AT7: 5.9136083 | AU7: 0 | AV7: 0 | AW7: 46.839076 | AX7: 105.3071 | AY7: 32.320658 | AZ7: 0 | BA7: 0 | BB7: -2.8218308 | BC7: 6.1515241 | BD7: 256.28078 | BE7: 34.528187 | BF7: 0 | BG7: 0 | BH7: 0 | BI7: 0 | BJ7: 0 | BK7: 0 | BL7: 0 | BM7: 0 | BN7: 0 | BO7: 0 | BP7: 0 | BQ7: 0 | BR7: 0 | BS7: 0 | BT7: -0.084116378 | BU7: 2.2968496 | BV7: 19.148853 | BW7: 45.416481 | BX7: 0 | BY7: 0 | BZ7: 0 | CA7: 0.020817194 | CB7: 18.456309 | CC7: 0 | CD7: 0 | CE7: 0 | CF7: 0 | CG7: 0 | CH7: 0 | CI7: 3.1949885 | CJ7: 6.0141214 | CK7: 3.1949885 | CL7: 10.350069 | CM7: 0 | CN7: -3.0423184 | CO7: 0.027113645 | CP7: 0.20544148 | CQ7: 0 | CR7: 0 | CS7: 0 | CT7: 372.38106 | CU7: -967.953 | CV7: -930.96633 | CW7: 179.49514 | CX7: 0.96178877 | CY7: 0.48202006 | CZ7: 3.451007 | DA7: 1.1143125 | DB7: 20.697363 | DC7: 1.162 | DD7: 100 | DE7: 40.878 | DF7: 9.6219475 | DG7: 56.785264
A9: Go4-26_BiggerDomain_FullCar_2__1__-2degyaw_10ms---_Reports.csv | B9: -2 | C9: 10 | D9: 239.44479 | E9: 93.204865 | F9: =D9/(0.5*DC9*DA9*(DB9^2)) -> 3.4109294 | G9: 1.3277183 | H9: 1.5264309 | I9: 0.59607276 | J9: 2.569016 | K9: 63.414031 | L9: 36.585969 | M9: 3.4023786 | N9: 2.0304961e-05 | O9: 0.0013243978 | P9: 1.3292505 | Q9: 8.1168276e-06 | R9: 0.0021433166 | S9: 63.405497 | T9: 0.0049327329 | U9: 0.0011076866 | V9: 87.145655 | W9: 18.979896 | X9: 67.783484 | Y9: 5.587262 | Z9: 4.3328975 | AA9: 2.0366791 | AB9: 2.2237666 | AC9: 2.6411456 | AD9: 2.5329143 | AE9: 2.0264272 | AF9: 2.0190441 | AG9: 3.6918705 | AH9: 4.0419748 | AI9: 0.43343022 | AJ9: 0.70616142 | AK9: 1.6181269 | AL9: 0.32834257 | AM9: 0.43015406 | AN9: 0 | AO9: 0 | AP9: 90.651078 | AQ9: 47.21956 | AR9: 68.026263 | AS9: 20.494855 | AT9: 1.4564591 | AU9: 0 | AV9: 0 | AW9: 11.817531 | AX9: 25.976536 | AY9: 8.0314105 | AZ9: 0 | BA9: 0 | BB9: -0.78295859 | BC9: 1.3940825 | BD9: 62.45995 | BE9: 8.7409298 | BF9: 0 | BG9: 0 | BH9: 0 | BI9: 0 | BJ9: 0 | BK9: 0 | BL9: 0 | BM9: 0 | BN9: 0 | BO9: 0 | BP9: 0 | BQ9: 0 | BR9: 0 | BS9: 0 | BT9: -0.035280403 | BU9: 0.65522803 | BV9: 6.0023164 | BW9: 10.995808 | BX9: 0 | BY9: 0 | BZ9: 0 | CA9: -0.14008455 | CB9: 4.6482735 | CC9: 0 | CD9: 0 | CE9: 0 | CF9: 0 | CG9: 0 | CH9: 0 | CI9: 0.9579222 | CJ9: 1.6816369 | CK9: 0.9579222 | CL9: 2.6763458 | CM9: 0 | CN9: -0.653421 | CO9: -0.069880956 | CP9: 0.10777914 | CQ9: 0 | CR9: 0 | CS9: 0 | CT9: 93.204865 | CU9: -239.44479 | CV9: -229.92308 | CW9: 44.363963 | CX9: 0.96023422 | CY9: 0.47598334 | CZ9: 3.451659 | DA9: 1.1137216 | DB9: 10.415735 | DC9: 1.162 | DD9: 100 | DE9: 472.563 | DF9: 107.93394 | DG9: 485.70271
A10: Go4-26_BiggerDomain_FullCar_2_-4degyaw_10ms_Reports.csv | B10: -4 | C10: 10 | D10: 235.03387 | E10: 91.650569 | F10: =D10/(0.5*DC10*DA10*(DB10^2)) -> 3.346445 | G10: 1.3049336 | H10: 1.4975733 | I10: 0.58555498 | J10: 2.5644562 | K10: 63.785716 | L10: 36.214284 | M10: 3.3360393 | N10: 1.3098835e-06 | O10: 0.00034307193 | P10: 1.304598 | Q10: 1.4341268e-08 | R10: 9.1794583e-05 | S10: 63.777174 | T10: 5.9026182e-05 | U10: 0.00012046394 | V10: 86.348361 | W10: 18.833513 | X10: 67.163895 | Y10: 5.5481231 | Z10: 4.2704704 | AA10: 2.0498973 | AB10: 2.1670687 | AC10: 2.6412671 | AD10: 2.4938515 | AE10: 1.9914404 | AF10: 2.0225922 | AG10: 3.6328188 | AH10: 3.9837508 | AI10: 0.43602397 | AJ10: 0.72913189 | AK10: 1.624022 | AL10: 0.33706602 | AM10: 0.45763611 | AN10: 0 | AO10: 0 | AP10: 88.501424 | AQ10: 45.887687 | AR10: 66.692156 | AS10: 19.807232 | AT10: 1.4015439 | AU10: 0 | AV10: 0 | AW10: 11.532149 | AX10: 25.175785 | AY10: 7.8688046 | AZ10: 0 | BA10: 0 | BB10: -0.80105205 | BC10: 1.3109485 | BD10: 61.150122 | BE10: 8.3746346 | BF10: 0 | BG10: 0 | BH10: 0 | BI10: 0 | BJ10: 0 | BK10: 0 | BL10: 0 | BM10: 0 | BN10: 0 | BO10: 0 | BP10: 0 | BQ10: 0 | BR10: 0 | BS10: 0 | BT10: -0.00589955 | BU10: 0.62313452 | BV10: 6.0579768 | BW10: 10.997761 | BX10: 0 | BY10: 0 | BZ10: 0 | CA10: -0.19368879 | CB10: 4.5926493 | CC10: 0 | CD10: 0 | CE10: 0 | CF10: 0 | CG10: 0 | CH10: 0 | CI10: 1.0485571 | CJ10: 1.9861913 | CK10: 1.0485571 | CL10: 2.6047616 | CM10: 0 | CN10: -0.36458363 | CO10: -0.081105949 | CP10: 0.11093237 | CQ10: 0 | CR10: 0 | CS10: 0 | CT10: 91.650569 | CU10: -235.03387 | CV10: -223.98906 | CW10: 43.229143 | CX10: 0.95300761 | CY10: 0.47167349 | CZ10: 3.4516555 | DA10: 1.1142708 | DB10: 10.415735 | DC10: 1.162 | DD10: 100 | DE10: 25.32 | DF10: 4.1648583 | DG10: 25.156862
A11: Go4-26_BiggerDomain_FullCar_2_NEG6degyaw_10ms_Copy_Reports.csv | B11: -6 | C11: 10 | D11: 242.03201 | E11: 94.595933 | F11: =D11/(0.5*DC11*DA11*(DB11^2)) -> 3.4459616 | G11: 1.3468217 | H11: 1.5421082 | I11: 0.60432942 | J11: 2.5585879 | K11: 62.974173 | L11: 37.025827 | M11: 3.4346251 | N11: 9.2746896e-07 | O11: 0.00028039506 | P11: 1.3465306 | Q11: 2.5277364e-07 | R11: 0.00037337881 | S11: 62.969336 | T11: 0.00011474688 | U11: 0.0001701145 | V11: 86.790811 | W11: 18.770706 | X11: 67.387318 | Y11: 5.6042092 | Z11: 4.3658496 | AA11: 2.0534553 | AB11: 2.2149027 | AC11: 2.3912927 | AD11: 2.5419952 | AE11: 2.0337955 | AF11: 2.0326436 | AG11: 3.6736595 | AH11: 4.0262299 | AI11: 0.43371106 | AJ11: 0.7051359 | AK11: 1.6447542 | AL11: 0.33956638 | AM11: 0.43933976 | AN11: 0 | AO11: 0 | AP11: 91.824699 | AQ11: 48.358737 | AR11: 68.791488 | AS11: 20.916386 | AT11: 1.4368549 | AU11: 0 | AV11: 0 | AW11: 12.220649 | AX11: 26.596907 | AY11: 7.9577103 | AZ11: 0 | BA11: 0 | BB11: -0.75688496 | BC11: 1.5834709 | BD11: 63.873198 | BE11: 8.8894415 | BF11: 0 | BG11: 0 | BH11: 0 | BI11: 0 | BJ11: 0 | BK11: 0 | BL11: 0 | BM11: 0 | BN11: 0 | BO11: 0 | BP11: 0 | BQ11: 0 | BR11: 0 | BS11: 0 | BT11: -0.017923399 | BU11: 0.66783493 | BV11: 6.4189325 | BW11: 11.402113 | BX11: 0 | BY11: 0 | BZ11: 0 | CA11: -0.14566977 | CB11: 4.6865924 | CC11: 0 | CD11: 0 | CE11: 0 | CF11: 0 | CG11: 0 | CH11: 0 | CI11: 0.96347707 | CJ11: 1.4723908 | CK11: 0.96347707 | CL11: 2.7118191 | CM11: 0 | CN11: -0.81711972 | CO11: -0.05240356 | CP11: 0.10643042 | CQ11: 0 | CR11: 0 | CS11: 0 | CT11: 94.595933 | CU11: -242.03201 | CV11: -234.47739 | CW11: 45.30504 | CX11: 0.9687867 | CY11: 0.47893222 | CZ11: 3.451008 | DA11: 1.1143109 | DB11: 10.415735 | DC11: 1.162 | DD11: 100 | DE11: 47.777 | DF11: 3.5341664 | DG11: 25.445998
A13: Go4-26_BiggerDomain_FullCar_2_-4degyaw_15ms_Copy_Reports.csv | B13: -4 | C13: 15 | D13: 941.42909 | E13: 355.99431 | F13: =D13/(0.5*DC13*DA13*(DB13^2)) -> 5.974504 | G13: 2.2592136 | H13: 2.6736605 | I13: 1.0137633 | J13: 2.644506 | K13: 64.243045 | L13: 35.756955 | M13: 3.4037462 | N13: 3.1647045e-06 | O13: 0.00052264814 | P13: 1.2934946 | Q13: 6.2486087e-06 | R13: 0.0019325335 | S13: 64.159135 | T13: 0.002398091 | U13: 0.00076326321 | V13: 348.69973 | W13: 75.031258 | X13: 271.31649 | Y13: 22.353834 | Z13: 16.893306 | AA13: 8.3419868 | AB13: 8.7700526 | AC13: 9.8671483 | AD13: 10.075559 | AE13: 7.8911848 | AF13: 8.1878526 | AG13: 14.723756 | AH13: 16.243321 | AI13: 1.8025061 | AJ13: 2.9782367 | AK13: 6.39177 | AL13: 1.3704724 | AM13: 1.7997586 | AN13: 0 | AO13: 0 | AP13: 352.59323 | AQ13: 178.20227 | AR13: 267.4067 | AS13: 76.484253 | AT13: 5.7217975 | AU13: 0 | AV13: 0 | AW13: 43.848816 | AX13: 97.350566 | AY13: 31.932979 | AZ13: 0 | BA13: 0 | BB13: -2.7413193 | BC13: 5.0699077 | BD13: 247.20415 | BE13: 33.094199 | BF13: 0 | BG13: 0 | BH13: 0 | BI13: 0 | BJ13: 0 | BK13: 0 | BL13: 0 | BM13: 0 | BN13: 0 | BO13: 0 | BP13: 0 | BQ13: 0 | BR13: 0 | BS13: 0 | BT13: -0.065552557 | BU13: 2.12613 | BV13: 19.784565 | BW13: 43.203682 | BX13: 0 | BY13: 0 | BZ13: 0 | CA13: 0.012560475 | CB13: 17.425517 | CC13: 0 | CD13: 0 | CE13: 0 | CF13: 0 | CG13: 0 | CH13: 0 | CI13: 3.7113854 | CJ13: 6.9005011 | CK13: 3.7113854 | CL13: 9.4699071 | CM13: 0 | CN13: -2.4154166 | CO13: -0.094487622 | CP13: 0.22315145 | CQ13: 0 | CR13: 0 | CS13: 0 | CT13: 355.99431 | CU13: -941.42909 | CV13: -888.81814 | CW13: 168.35469 | CX13: 0.94411587 | CY13: 0.47291401 | CZ13: 3.4516555 | DA13: 1.1142708 | DB13: 15.601252 | DC13: 1.162 | DD13: 100 | DE13: 49.926 | DF13: 6.9451094 | DG13: 25.002394
A14: Go4-26_BiggerDomain_FullCar_2_NEG6degyaw_15ms_Reports.csv | B14: -6 | C14: 15 | D14: 547.05808 | E14: 211.61707 | F14: =D14/(0.5*DC14*DA14*(DB14^2)) -> 3.4915995 | G14: 1.3506465 | H14: 1.5625317 | I14: 0.60604563 | J14: 2.5851321 | K14: 63.15459 | L14: 36.84541 | M14: 3.4826994 | N14: 2.1407812e-07 | O14: 0.00013285263 | P14: 1.350686 | Q14: 1.8701804e-07 | R14: 0.00032017496 | S14: 63.166537 | T14: 6.0484414e-05 | U14: 0.00012312172 | V14: 196.69877 | W14: 42.296521 | X14: 152.7595 | Y14: 12.68702 | Z14: 9.8131128 | AA14: 4.6849154 | AB14: 5.036724 | AC14: 5.1457621 | AD14: 5.7660581 | AE14: 4.5759135 | AF14: 4.6188626 | AG14: 8.3799304 | AH14: 9.1073939 | AI14: 0.99613238 | AJ14: 1.6139653 | AK14: 3.6751014 | AL14: 0.77318693 | AM14: 0.98177562 | AN14: 0 | AO14: 0 | AP14: 207.45313 | AQ14: 108.34345 | AR14: 155.55632 | AS14: 46.901452 | AT14: 3.2989054 | AU14: 0 | AV14: 0 | AW14: 27.111433 | AX14: 59.701818 | AY14: 18.004509 | AZ14: 0 | BA14: 0 | BB14: -1.6024497 | BC14: 3.5256863 | BD14: 144.66863 | BE14: 19.817039 | BF14: 0 | BG14: 0 | BH14: 0 | BI14: 0 | BJ14: 0 | BK14: 0 | BL14: 0 | BM14: 0 | BN14: 0 | BO14: 0 | BP14: 0 | BQ14: 0 | BR14: 0 | BS14: 0 | BT14: -0.040405494 | BU14: 1.3661222 | BV14: 13.427976 | BW14: 26.005365 | BX14: 0 | BY14: 0 | BZ14: 0 | CA14: -0.10026222 | CB14: 10.250487 | CC14: 0 | CD14: 0 | CE14: 0 | CF14: 0 | CG14: 0 | CH14: 0 | CI14: 1.9343841 | CJ14: 3.3250911 | CK14: 1.9343841 | CL14: 5.8384913 | CM14: 0 | CN14: -1.9891943 | CO14: -0.062756259 | CP14: 0.15691928 | CQ14: 0 | CR14: 0 | CS14: 0 | CT14: 211.61707 | CU14: -547.05808 | CV14: -528.06362 | CW14: 101.59408 | CX14: 0.96527889 | CY14: 0.48008453 | CZ14: 3.451008 | DA14: 1.1143109 | DB14: 15.556549 | DC14: 1.162 | DD14: 100 | DE14: 44.234 | DF14: 3.4805294 | DG14: 25.059812
A15: Go4-26_BiggerDomain_FullCar_2_NEG8degyaw_15ms_Reports.csv | B15: -8 | C15: 15 | D15: 489.79078 | E15: 192.76463 | F15: =D15/(0.5*DC15*DA15*(DB15^2)) -> 3.1259409 | G15: 1.2302617 | H15: 1.3988952 | I15: 0.5520016 | J15: 2.5408748 | K15: 65.959935 | L15: 34.040065 | M15: 3.1305646 | N15: 3.6591412e-05 | O15: 0.001932266 | P15: 1.2361451 | Q15: 1.0839797e-05 | R15: 0.002663429 | S15: 65.722239 | T15: 0.012896463 | U15: 0.0017279173 | V15: 189.17215 | W15: 40.115797 | X15: 147.73684 | Y15: 12.111425 | Z15: 8.9842108 | AA15: 4.5373566 | AB15: 4.5834938 | AC15: 5.1298098 | AD15: 5.4823031 | AE15: 4.1551802 | AF15: 4.4887223 | AG15: 7.8382453 | AH15: 8.7287853 | AI15: 0.97774387 | AJ15: 1.5122901 | AK15: 3.472398 | AL15: 0.74548761 | AM15: 0.9654056 | AN15: 0 | AO15: 0 | AP15: 177.09612 | AQ15: 92.319982 | AR15: 134.12035 | AS15: 38.358057 | AT15: 2.9983312 | AU15: 0 | AV15: 0 | AW15: 22.070048 | AX15: 49.938612 | AY15: 17.625513 | AZ15: 0 | BA15: 0 | BB15: -1.3789565 | BC15: 2.6858077 | BD15: 128.36211 | BE15: 17.70737 | BF15: 0 | BG15: 0 | BH15: 0 | BI15: 0 | BJ15: 0 | BK15: 0 | BL15: 0 | BM15: 0 | BN15: 0 | BO15: 0 | BP15: 0 | BQ15: 0 | BR15: 0 | BS15: 0 | BT15: -0.16253244 | BU15: 1.1679871 | BV15: 12.153773 | BW15: 24.116474 | BX15: 0 | BY15: 0 | BZ15: 0 | CA15: -0.26803343 | CB15: 9.5028 | CC15: 0 | CD15: 0 | CE15: 0 | CF15: 0 | CG15: 0 | CH15: 0 | CI15: 2.9032707 | CJ15: 6.7355774 | CK15: 2.9032707 | CL15: 5.3371911 | CM15: 0 | CN15: -0.11641647 | CO15: -0.49550286 | CP15: 0.17173051 | CQ15: 0 | CR15: 0 | CS15: 0 | CT15: 192.76463 | CU15: -489.79078 | CV15: -446.06941 | CW15: 88.305504 | CX15: 0.9107346 | CY15: 0.45810014 | CZ15: 3.4510638 | DA15: 1.1143643 | DB15: 15.556549 | DC15: 1.162 | DD15: 100 | DE15: 44.936 | DF15: 3.8150664 | DG15: 27.468478
A17: 25 CFD DATA
A18: Sim ID | B18: Velocity | C18: Velocity | D18: Yaw Angle | E18: Run by | F18: Downforce ALL | G18: Drag ALL | H18: -Cl | I18: Cd | J18: ClA | K18: CdA | L18: Aerodynamic Efficiency | M18: Percent downforce on front tire | N18: Percent downforce on rear tire | O18: Cl Mean | P18: Cl Variance | Q18: Cl CoV | R18: Cd Mean | S18: Cd Variance | T18: Cd CoV | U18: AeroBalance Mean | V18: AeroBalance Variance | W18: AeroBalance CoV | X18: Downforce Front Wing ALL | Y18: Drag Front Wing ALL | Z18: Downforce wing front 1 | AA18: Downforce wing front 2 | AB18: Downforce wing front 3 | AC18: Downforce wing front 4 | AD18: Downforce wing front 5 | AE18: Drag wing front 1 | AF18: Drag wing front 2 | AG18: Drag wing front 3 | AH18: Drag wing front 4 | AI18: Drag wing front 5 | AJ18: Downforce wing front end plate 1 | AK18: Downforce wing front end plate 2 | AL18: Downforce wing front end plate 3 | AM18: Drag wing front end plate 1 | AN18: Drag wing front end plate 2 | AO18: Drag wing front end plate 3 | AP18: Downforce Jacking Bar | AQ18: Drag Jacking Bar | AR18: Downforce Rear Wing ALL | AS18: Drag Rear Wing ALL | AT18: Downforce wing rear 1 | AU18: Downforce wing rear 2 | AV18: Downforce wing rear 3 | AW18: Downforce wing rear 4 | AX18: Downforce wing rear 5 | AY18: Drag wing rear 1 | AZ18: Drag wing rear 2 | BA18: Drag wing rear 3 | BB18: Drag wing rear 4 | BC18: Drag wing rear 5 | BD18: Downforce wing rear end plate | BE18: Drag wing rear end plate | BF18: Downforce Sidepods | BG18: Drag Sidepods | BH18: Downforce wing side 1 | BI18: Downforce wing side 2 | BJ18: Downforce wing side 3 | BK18: Downforce wing side 4 | BL18: Drag wing side 1 | BM18: Drag wing side 2 | BN18: Drag wing side 3 | BO18: Drag wing side 4 | BP18: Downforce Suspension Covers | BQ18: Drag Suspension Covers | BR18: Downforce Moustaches | BS18: Drag Moustaches | BT18: Downforce Diffuser | BU18: Drag Diffuser | BV18: Downforce Chassis | BW18: Drag Chassis | BX18: Downforce Center body | BY18: Drag Center body | BZ18: Nosecone Cl | CA18: Nosecone Cd | CB18: Nosecone FA | CC18: Downforce Suspension | CD18: Drag Suspension | CE18: Downforce Powertrain | CF18: Drag Powertrain | CG18: Downforce Mounts | CH18: Drag Mounts | CI18: Downforce Intake manifold | CJ18: Drag Intake manifold | CK18: Drag wheel front | CL18: Drag wheel rear | CM18: Front Tire Drag | CN18: Drag driver | CO18: Drag head rest | CP18: Downforce Radiator Shrouds | CQ18: Drag Radiator Shrouds | CR18: Radiator Mass Flow | CS18: Surface Average Fan Velocity | CT18: Fan volumetric flow rate | CU18: Mass Flow of fan | CV18: Force_x | CW18: Force_y | CX18: XF_Z | CY18: ZF_X | CZ18: X_Coord | DA18: Z_Coord | DB18: Planform area of the car | DC18: Frontal area of the car | DD18: Simulation Velocity | DE18: Density of Air | DF18: CFL Number | DG18: Solver Iteration Elapsed Time | DH18: Total Solver Elapsed Time | DI18: Average Solver Iteration Time | DJ18: Residual_Continuity | DK18: Residual_X-momentum | DL18: Residual_Y-momentum | DM18: Residual_Z-momentum | DN18: Residual_Tke | DO18: Residual_Sdr
A19: 1.1 | B19: 10.415735 | C19: 23.3 | D19: 0 | E19: Sean | F19: 110.569 | G19: 62.738602 | H19: 1.6246541 | I19: 0.99647972 | J19: 0.78590753 | K19: 0.45977804 | L19: 1.7623759 | M19: 57.435575 | N19: 42.564425 | O19: 1.2999901 | P19: 0.13121655 | Q19: 0.27864693 | R19: 0.81088459 | S19: 0.028386334 | T19: 0.20777611 | U19: 53.53592 | V19: 32.191563 | W19: 0.10598045 | X19: 53.077436 | Y19: 13.177125 | Z19: 39.280229 | AA19: 3.9825818 | AB19: 2.5901432 | AC19: 1.7034708 | AD19: 1.1804028 | AE19: 2.022634 | AF19: 1.8430271 | AG19: 1.1936396 | AH19: 1.676413 | AI19: 2.0646762 | AJ19: 0.35638232 | AK19: 0.23573442 | AL19: 3.7484912 | AM19: 0.36174122 | AN19: 0.21494632 | AO19: 1.7353713 | AP19: 0 | AQ19: 0 | AR19: 52.964351 | AS19: 30.043181 | AT19: 38.761969 | AU19: 12.891512 | AV19: 0.91469 | AW19: 0 | AX19: 0 | AY19: 6.3780621 | AZ19: 16.456882 | BA19: 6.4916072 | BB19: 0 | BC19: 0 | BD19: -0.51851037 | BE19: 0.71663026 | BF19: 19.897235 | BG19: 3.2303951 | BH19: 0 | BI19: 0 | BJ19: 0 | BK19: 0 | BL19: 0 | BM19: 0 | BN19: 0 | BO19: 0 | BP19: 0 | BQ19: 0 | BR19: -3.5566857 | BS19: -0.25468886 | BT19: 10.228943 | BU19: 1.2309716 | BV19: 0.71936239 | BW19: 3.773555 | BX19: -1.6012202 | BY19: 3.5283681 | BZ19: 0 | CA19: 0 | CB19: 0 | CC19: -0.69012894 | CD19: 2.2331831 | CE19: 0 | CF19: 0 | CG19: -0.025212099 | CH19: 1.5688064 | CI19: 0 | CJ19: 0 | CK19: 1.1412445 | CL19: 1.9160774 | CM19: 1.1412445 | CN19: 0.65201218 | CO19: 1.4143145 | CP19: 0.22816072 | CQ19: -0.10388044 | CR19: 0.040353632 | CS19: 0 | CT19: 0 | CU19: 0 | CV19: 62.738602 | CW19: -110.569 | CX19: -117.13952 | CY19: 27.780775 | CZ19: 1.0594246 | DA19: 0.44280195 | DB19: 3.4672965 | DC19: 1.083653 | DD19: 10 | DE19: 1.162 | DF19: 100 | DG19: 8.9091208 | DH19: 0.1520699 | DI19: 5.4203133 | DJ19: 0.00046 | DK19: 0.0018135609 | DL19: 0.0012997636 | DM19: 0.0016924473 | DN19: 4.45e-05 | DO19: 0.019729711
A20: 1.2 | B20: 13.008494 | C20: 29.1 | D20: 0 | E20: Sean | F20: 174.31417 | G20: 100.98819 | H20: 1.6420489 | I20: 0.94911206 | J20: 0.73313512 | K20: 0.43792249 | L20: 1.7260847 | M20: 56.462049 | N20: 43.537951 | O20: 1.2438041 | P20: 0.11028875 | Q20: 0.26700145 | R20: 0.78189903 | S20: 0.026384426 | T20: 0.20774145 | U20: 52.767599 | V20: 29.387566 | W20: 0.10273407 | X20: 84.13605 | Y20: 21.273478 | Z20: 61.898713 | AA20: 6.4535539 | AB20: 4.1179809 | AC20: 2.7911908 | AD20: 1.8788066 | AE20: 3.3643501 | AF20: 2.9585341 | AG20: 1.8736557 | AH20: 2.7380168 | AI20: 3.3048163 | AJ20: 0.58712241 | AK20: 0.3829992 | AL20: 6.0256836 | AM20: 0.58864484 | AN20: 0.33487793 | AO20: 2.8057663 | AP20: 0 | AQ20: 0 | AR20: 87.564297 | AS20: 49.421853 | AT20: 63.934486 | AU20: 21.430255 | AV20: 1.5224771 | AW20: 0 | AX20: 0 | AY20: 10.189206 | AZ20: 27.20636 | BA20: 10.886252 | BB20: 0 | BC20: 0 | BD20: -0.84539872 | BE20: 1.1400365 | BF20: 27.727471 | BG20: 4.8111219 | BH20: 0 | BI20: 0 | BJ20: 0 | BK20: 0 | BL20: 0 | BM20: 0 | BN20: 0 | BO20: 0 | BP20: 0 | BQ20: 0 | BR20: -5.8175238 | BS20: -0.40441974 | BT20: 15.224859 | BU20: 1.7869562 | BV20: 1.3345761 | BW20: 6.4044556 | BX20: -4.9220352 | BY20: 5.5213936 | BZ20: 0 | CA20: 0 | CB20: 0 | CC20: -1.057742 | CD20: 3.4552942 | CE20: 0 | CF20: 0 | CG20: -0.046261657 | CH20: 2.5118401 | CI20: 0 | CJ20: 0 | CK20: 1.7817791 | CL20: 2.5777501 | CM20: 1.7817791 | CN20: 1.0238876 | CO20: 2.3820594 | CP20: 0.3787581 | CQ20: -0.19019904 | CR20: 0.053234648 | CS20: 0 | CT20: 0 | CU20: 0 | CV20: 100.98819 | CW20: -174.31417 | CX20: -188.05206 | CY20: 45.725743 | CZ20: 1.0788111 | DA20: 0.45278307 | DB20: 3.4672965 | DC20: 1.083653 | DD20: 13 | DE20: 1.162 | DF20: 100 | DG20: 8.8032237 | DH20: 0.15610318 | DI20: 5.5640737 | DJ20: 0.000289 | DK20: 0.0012648498 | DL20: 0.000843 | DM20: 0.000651 | DN20: 3.2e-05 | DO20: 0.020191466
A21: 1.3 | B21: 15.601252 | C21: 34.9 | D21: 0 | E21: Sean | F21: 283.55613 | G21: 162.15574 | H21: 1.857067 | I21: 1.0060648 | J21: 0.78729432 | K21: 0.46420061 | L21: 1.7486655 | M21: 57.442983 | N21: 42.557017 | O21: 1.2826455 | P21: 0.11854956 | Q21: 0.26843759 | R21: 0.79388085 | S21: 0.027884139 | T21: 0.21034069 | U21: 53.89559 | V21: 24.106025 | W21: 0.091098152 | X21: 137.61176 | Y21: 34.026644 | Z21: 101.61035 | AA21: 10.360466 | AB21: 6.7508139 | AC21: 4.4376544 | AD21: 3.1311143 | AE21: 4.9810543 | AF21: 4.7827136 | AG21: 3.0992119 | AH21: 4.3472702 | AI21: 5.4376585 | AJ21: 0.92594139 | AK21: 0.6205211 | AL21: 9.7748975 | AM21: 0.92509387 | AN21: 0.5537202 | AO21: 4.4622625 | AP21: 0 | AQ21: 0 | AR21: 139.92682 | AS21: 79.420665 | AT21: 101.99442 | AU21: 34.276045 | AV21: 2.4969472 | AW21: 0 | AX21: 0 | AY21: 16.866388 | AZ21: 43.562413 | BA21: 17.125279 | BB21: 0 | BC21: 0 | BD21: -1.3375463 | BE21: 1.8665842 | BF21: 46.743908 | BG21: 8.4412493 | BH21: 0 | BI21: 0 | BJ21: 0 | BK21: 0 | BL21: 0 | BM21: 0 | BN21: 0 | BO21: 0 | BP21: 0 | BQ21: 0 | BR21: -9.1699005 | BS21: -0.71133205 | BT21: 23.493 | BU21: 2.5436757 | BV21: 1.7350389 | BW21: 9.5622992 | BX21: -5.9329841 | BY21: 9.7919059 | BZ21: 0 | CA21: 0 | CB21: 0 | CC21: -1.8419356 | CD21: 5.7215623 | CE21: 0 | CF21: 0 | CG21: -0.055104387 | CH21: 4.1061207 | CI21: 0 | CJ21: 0 | CK21: 2.5604733 | CL21: 3.9886669 | CM21: 2.5604733 | CN21: 1.6550105 | CO21: 3.7196205 | CP21: 0.64045285 | CQ21: -0.26579245 | CR21: 0.065056899 | CS21: 0 | CT21: 0 | CU21: 0 | CV21: 162.15574 | CW21: -283.55613 | CX21: -300.36451 | CY21: 73.402589 | CZ21: 1.0592771 | DA21: 0.45266724 | DB21: 3.4672965 | DC21: 1.083653 | DD21: 16 | DE21: 1.162 | DF21: 100 | DG21: 7.8557535 | DH21: 0.14203726 | DI21: 5.0627142 | DJ21: 0.00057 | DK21: 0.0034871622 | DL21: 0.0020818214 | DM21: 0.0016186945 | DN21: 2.99e-05 | DO21: 0.020544864
A22: 1.4 | B22: 18.104604 | C22: 40.5 | D22: 0 | E22: Sean | F22: 325.29984 | G22: 187.72426 | H22: 1.5820244 | I22: 0.92025675 | J22: 0.71363619 | K22: 0.42460858 | L22: 1.7328599 | M22: 56.73477 | N22: 43.26523 | O22: 1.2609406 | P22: 0.094458557 | Q22: 0.24373956 | R22: 0.77483187 | S22: 0.023282575 | T22: 0.19692825 | U22: 53.67066 | V22: 20.132977 | W22: 0.083602077 | X22: 158.9394 | Y22: 40.520866 | Z22: 116.33339 | AA22: 12.320221 | AB22: 7.9027265 | AC22: 5.3519733 | AD22: 3.6650538 | AE22: 6.238443 | AF22: 5.6227371 | AG22: 3.5615461 | AH22: 5.2320053 | AI22: 6.389539 | AJ22: 1.1182127 | AK22: 0.73832603 | AL22: 11.50949 | AM22: 1.1061348 | AN22: 0.63426905 | AO22: 5.346653 | AP22: 0 | AQ22: 0 | AR22: 164.35805 | AS22: 91.956968 | AT22: 119.96244 | AU22: 40.193107 | AV22: 2.8591897 | AW22: 0 | AX22: 0 | AY22: 18.471352 | AZ22: 50.810716 | BA22: 20.598931 | BB22: 0 | BC22: 0 | BD22: -1.5158787 | BE22: 2.075969 | BF22: 48.214314 | BG22: 9.1534778 | BH22: 0 | BI22: 0 | BJ22: 0 | BK22: 0 | BL22: 0 | BM22: 0 | BN22: 0 | BO22: 0 | BP22: 0 | BQ22: 0 | BR22: -10.800113 | BS22: -0.70332274 | BT22: 26.957717 | BU22: 2.9881056 | BV22: 1.7689293 | BW22: 10.81728 | BX22: -9.5936395 | BY22: 11.57616 | BZ22: 0 | CA22: 0 | CB22: 0 | CC22: -1.9686412 | CD22: 6.3469425 | CE22: 0 | CF22: 0 | CG22: -0.042625239 | CH22: 4.6160225 | CI22: 0 | CJ22: 0 | CK22: 3.054268 | CL22: 4.2851847 | CM22: 3.054268 | CN22: 1.8820265 | CO22: 4.5898078 | CP22: 0.80922871 | CQ22: -0.36686732 | CR22: 0.075317904 | CS22: 0 | CT22: 0 | CU22: 0 | CV22: 187.72426 | CW22: -325.29984 | CX22: -349.1704 | CY22: 85.449852 | CZ22: 1.0733802 | DA22: 0.45518811 | DB22: 3.4672965 | DC22: 1.083653 | DD22: 18 | DE22: 1.162 | DF22: 100 | DG22: 9.3194553 | DH22: 0.21681312 | DI22: 7.7279925 | DJ22: 0.0010486628 | DK22: 0.0070519699 | DL22: 0.0081982616 | DM22: 0.0075227151 | DN22: 0.001494641 | DO22: 0.16413226
A23: 1.5 | B23: 20.697363 | C23: 46.3 | D23: 0 | E23: Sean | F23: 498.23414 | G23: 278.59162 | H23: 1.8540049 | I23: 1.0033745 | J23: 0.80303214 | K23: 0.46295932 | L23: 1.7884032 | M23: 57.275471 | N23: 42.724529 | O23: 1.402161 | P23: 0.1126652 | Q23: 0.23938503 | R23: 0.82760584 | S23: 0.026218785 | T23: 0.1956513 | U23: 54.743863 | V23: 15.427392 | W23: 0.071748169 | X23: 239.68893 | Y23: 58.662163 | Z23: 177.36797 | AA23: 17.965936 | AB23: 11.668454 | AC23: 7.6740044 | AD23: 5.4897865 | AE23: 8.2435717 | AF23: 8.296596 | AG23: 5.3289854 | AH23: 7.5050395 | AI23: 9.5679764 | AJ23: 1.5989722 | AK23: 1.0967464 | AL23: 16.827068 | AM23: 1.5714688 | AN23: 0.96214802 | AO23: 7.6184008 | AP23: 0 | AQ23: 0 | AR23: 242.36398 | AS23: 135.97515 | AT23: 176.87796 | AU23: 59.162745 | AV23: 4.3141058 | AW23: 0 | AX23: 0 | AY23: 28.25937 | AZ23: 75.092552 | BA23: 29.501696 | BB23: 0 | BC23: 0 | BD23: -2.3049298 | BE23: 3.1215306 | BF23: 86.815088 | BG23: 15.394458 | BH23: 0 | BI23: 0 | BJ23: 0 | BK23: 0 | BL23: 0 | BM23: 0 | BN23: 0 | BO23: 0 | BP23: 0 | BQ23: 0 | BR23: -15.771787 | BS23: -1.2516853 | BT23: 45.308991 | BU23: 4.962898 | BV23: 5.27984 | BW23: 19.347726 | BX23: -13.871626 | BY23: 14.179931 | BZ23: 0 | CA23: 0 | CB23: 0 | CC23: -3.2003785 | CD23: 9.5798005 | CE23: 0 | CF23: 0 | CG23: -0.17007792 | CH23: 7.0632254 | CI23: 0 | CJ23: 0 | CK23: 4.1152715 | CL23: 6.2702757 | CM23: 4.1152715 | CN23: 2.7996225 | CO23: 6.4597703 | CP23: 1.3208362 | CQ23: -0.47240949 | CR23: 0.087348023 | CS23: 0 | CT23: 0 | CU23: 0 | CV23: 278.59162 | CW23: -498.23414 | CX23: -529.43 | CY23: 125.94032 | CZ23: 1.0626129 | DA23: 0.4520607 | DB23: 3.4672965 | DC23: 1.083653 | DD23: 21 | DE23: 1.162 | DF23: 100 | DG23: 8.825475 | DH23: 0.19964128 | DI23: 7.1159268 | DJ23: 0.000564 | DK23: 0.0050133095 | DL23: 0.0026559132 | DM23: 0.0022561693 | DN23: 1.76e-05 | DO23: 0.011128895
